Workbook

Sheet Zoom Indicateurs 2025
A1: Zoom Indicateurs 2025 | B1: Suivi | C1: Objectifs 2025 | D1: Cumul 2025 | E1: Janvier | F1: Février | G1: Mars | H1: Avril | I1: Mai | J1: Juin | K1: Juillet | L1: Août | M1: Septembre | N1: Octobre | O1: Novembre | P1: Décembre | Q1: Cumul 2025
A2: PM02 : Manager, piloter, améliorer le SMQS
A3: Animation sécurité | B3: Annuel | C3: 11 | D3: =SUM(E3:P3) -> 9 | E3: 2 | F3: 0 | G3: 1 | H3: 1 | I3: 0 | J3: 2 | K3: 1 | L3: 0 | M3: 0 | N3: 0 | O3: 1 | P3: 1
A4: Fiches d'étonnements | B4: Annuel | C4: 0 | D4: =SUM(E4:P4) -> 0 | E4: 0 | F4: 0 | G4: 0 | H4: 0 | I4: 0 | J4: 0 | K4: 0 | L4: 0 | M4: 0 | N4: 0 | O4: 0 | P4: 0
A5: Audits terrain réalisées | B5: Annuel | C5: 8 | D5: =SUM(E5:P5) -> 4 | E5: 1 | F5: 0 | G5: 1 | H5: 0 | I5: 0 | J5: 0 | K5: 0 | L5: 0 | M5: 0 | N5: 1 | O5: 0 | P5: 1
A6: Audits processus réalisées | B6: Annuel | C6: 8 | D6: =SUM(E6:P6) -> 8 | E6: 1 | F6: 1 | G6: 0 | H6: 0 | I6: 0 | J6: 0 | K6: 0 | L6: 0 | M6: 0 | N6: 0 | O6: 4 | P6: 2
A7: Revues de direction | B7: Annuel | C7: 5 | D7: =SUM(E7:P7) -> 5 | E7: 0 | F7: 1 | G7: 0 | H7: 1 | I7: 1 | J7: 2 | K7: 0 | L7: 0 | M7: 0 | N7: 0 | O7: 0 | P7: 0
A8: Revues de processus | B8: Annuel | C8: 10 | D8: =SUM(E8:P8) -> 5 | E8: 0 | F8: 0 | G8: 0 | H8: 0 | I8: 0 | J8: 0 | K8: 0 | L8: 0 | M8: 0 | N8: 0 | O8: 3 | P8: 2
A9: Taux d'évaluation règlementaire FRANCE | B9: Trimestriel | C9: 0.95 | D9: =AVERAGE(E9:P9) -> 0.97 | G9: 0.97 | J9: 0.97 | M9: 0.97 | P9: 0.97
A10: Taux de conformité règlementaire FRANCE | B10: Trimestriel | C10: 0.85 | D10: 0.91 | G10: 0.9 | J10: 0.9 | M10: 0.91 | P10: 0.91
A11: Taux d'évaluation règlementaire Luxembourg | B11: Semestriel | C11: 0.95 | D11: =AVERAGE(E11:P11) -> 0.99 | G11: 0.99 | J11: 0.99 | M11: 0.99 | P11: 0.99
A12: Taux de conformité règlementaire Luxembourg | B12: Semestriel | C12: 0.8 | D12: =AVERAGE(E12:P12) -> 0.92 | G12: 0.92 | J12: 0.92 | M12: 0.92 | P12: 0.92
A13: AB Serve Group (Exploitation)
A14: Taux de fréquence | B14: Mensuel | C14: 18 | E14: 0 | F14: 0 | G14: 0 | H14: 0 | I14: 0 | J14: 0 | K14: 0 | L14: 0 | M14: 0 | N14: 0 | O14: 0 | P14: 0
A15: Taux de gravité | B15: Mensuel | C15: 0.5 | E15: 0 | F15: 0 | G15: 0 | H15: 0 | I15: 0 | J15: 0 | K15: 0 | L15: 0 | M15: 0 | N15: 0 | O15: 0 | P15: 0
A16: Nombre d'ATSA | B16: Mensuel | C16: 0 | E16: 0 | F16: 0 | G16: 0 | H16: 0 | I16: 0 | J16: 0 | K16: 0 | L16: 0 | M16: 0 | N16: 0 | O16: 0 | P16: 0
A17: Nombre d'ATA | B17: Mensuel | C17: 0 | E17: 0 | F17: 0 | G17: 0 | H17: 0 | I17: 0 | J17: 0 | K17: 0 | L17: 0 | M17: 0 | N17: 0 | O17: 0 | P17: 0
A18: Nombre d'analyse | B18: Mensuel | C18: 1 | E18: 0 | F18: 0 | G18: 0 | H18: 0 | I18: 0 | J18: 0 | K18: 0 | L18: 0 | M18: 0 | N18: 0 | O18: 0 | P18: 0
A19: Taux d'analyse | B19: Mensuel | C19: 1
A20: Nombre de réclamations et d'incidents client | B20: Mensuel | C20: 8
A21: AB Serve
A22: Taux de fréquence | B22: Glissant 12M | C22: 15 | D22: 19.26 | E22: 0 | F22: 0 | G22: 60.37 | H22: 47.67 | I22: 40.64 | J22: 35.31 | K22: 31.29 | L22: 29.75 | M22: 38.94 | N22: 34.08 | O22: 31.12 | P22: 28.9
A23: Taux de gravité | B23: Glissant 12M | C23: 0.35 | E23: 0 | F23: 0 | G23: 0.09 | H23: 0.79 | I23: 0.67 | J23: 0.58 | K23: 0.52 | L23: 0.49 | M23: 0.48 | N23: 0.42 | O23: 0.38 | P23: 0.36 | Q23: 0.32
A24: Nombre d'ATSA | B24: Mensuel | C24: 2 | D24: =SUM(E24:P24) -> 3 | E24: 0 | F24: 0 | G24: 2 | H24: 0 | I24: 0 | J24: 0 | K24: 0 | L24: 0 | M24: 0 | N24: 0 | O24: 1 | P24: 0
A25: Nombre d'ATA | B25: Mensuel | C25: 1 | D25: =SUM(E25:P25) -> 2 | E25: 0 | F25: 0 | G25: 0 | H25: 0 | I25: 0 | J25: 0 | K25: 1 | L25: 0 | M25: 1 | N25: 0 | O25: 0 | P25: 0
A26: Nombre d'analyse | B26: Mensuel | C26: - | D26: 5 | E26: - | F26: - | G26: 2 | H26: - | I26: - | J26: - | K26: 1 | L26: - | M26: 1 | N26: - | O26: 1 | P26: -
A27: Taux d'analyse | B27: Mensuel | C27: 1 | D27: =AVERAGE(E27:P27) -> 1 | E27: - | F27: - | G27: 1 | H27: - | I27: - | J27: - | K27: 1 | L27: - | M27: 1 | N27: - | O27: 1 | P27: -
A28: Nombre de réclamations et d'incidents client | B28: Mensuel | C28: 10 | D28: =SUM(E28:P28) -> 2 | E28: 0 | F28: 0 | G28: 0 | H28: 0 | I28: 0 | J28: 0 | K28: 1 | L28: 0 | M28: 0 | N28: 0 | O28: 1 | P28: 0
A29: Valoris Emploi
A30: Taux de fréquence | B30: Mensuel | C30: 25 | D30: 53.47 | E30: 27.841618 | F30: 35.726765 | G30: 43.645559 | H30: 44.803108 | I30: 46.438033 | J30: 40.254343 | K30: 42.79597 | L30: 43.814213 | M30: 45.370733 | N30: 57.308232 | O30: 51.335756 | P30: 53.466501
A31: Taux de gravité | B31: Mensuel | C31: 0.8 | D31: 0.67 | E31: 0.95357542 | F31: 1.1361111 | G31: 1.1638816 | H31: 1.3888964 | I31: 1.3776616 | J31: 1.3122916 | K31: 1.1982872 | L31: 1.0340154 | M31: 0.88926637 | N31: 0.97423995 | O31: 0.88297501 | P31: 0.67367791
A32: Nombre d'ATA | B32: Mensuel | C32: 2 | D32: =SUM(E32:P32) -> 5 | E32: 0 | F32: 1 | G32: 2 | H32: 1 | I32: 0 | J32: 0 | K32: 0 | L32: 0 | M32: 0 | N32: 1 | O32: 0 | P32: 0
A33: Nombre d'ATSA | B33: Mensuel | C33: 3 | D33: =SUM(E33:P33) -> 1 | E33: 0 | F33: 0 | G33: 0 | H33: 0 | I33: 0 | J33: 0 | K33: 0 | L33: 0 | M33: 0 | N33: 0 | O33: 1 | P33: 0
A34: nombre d'AT trajet | B34: Mensuel | C34: 0 | D34: =SUM(E34:P34) -> 1 | E34: 0 | F34: 0 | G34: 0 | H34: 0 | I34: 0 | J34: 1 | K34: 0 | L34: 0 | M34: 0 | N34: 0 | O34: 0 | P34: 0
A35: Nombre d'analyse réalisées ATA | B35: Mensuel | C35: - | D35: 7 | E35: 0 | F35: 1 | G35: 2 | H35: 1 | I35: 0 | J35: 1 | K35: 0 | L35: 0 | M35: 0 | N35: 1 | O35: 1 | P35: 0
A36: Taux d'analyse ATA | B36: Mensuel | C36: 1 | D36: 1 | E36: - | F36: 1 | G36: 1 | H36: 1 | I36: - | J36: 1 | K36: - | L36: - | M36: - | N36: 1 | O36: 1 | P36: -
A37: Nombre de réclamations et d'incidents client | B37: Mensuel | C37: 1 | D37: 0 | E37: 0 | F37: 0 | G37: 0 | H37: 0 | I37: 0 | J37: 0 | K37: 0 | L37: 0 | M37: 0 | N37: 0 | O37: 0 | P37: 0
A38: AB Serve GERMANY
A39: Taux de fréquence | B39: Mensuel | C39: 40 | E39: 0 | F39: 0 | G39: 0 | H39: 0 | I39: 0 | J39: 0 | K39: 0 | L39: 0 | M39: 0 | N39: 0 | O39: 0 | P39: 0
A40: Taux de gravité | B40: Mensuel | C40: 0.4 | E40: 0 | F40: 0 | G40: 0 | H40: 0 | I40: 0 | J40: 0 | K40: 0 | L40: 0 | M40: 0 | N40: 0 | O40: 0 | P40: 0
...

Sheet Synthèse PM02 2025
B1: Zoom Indicateurs PM02 2025 : Représentation Graphique
B2: Indicateur Générale AB Serve Group / Toute Société
B4: Animation Terrain Qualité - Sécurité - Environement | I4: Animation Système Qualité - Sécurité - Environement | P4: Veille réglementaire France et Luxembourg | W4: Veille réglementaire Luxembourg
B5: Audit terrain objectif | C5: ='Zoom Indicateurs 2025'!C5 -> 8 | D5: FAI objectif | E5: ='Zoom Indicateurs 2025'!C4 -> 0 | F5: fiche sécurité objectif | G5: ='Zoom Indicateurs 2025'!C3 -> 11 | I5: Audit processus obj. | J5: ='Zoom Indicateurs 2025'!C6 -> 8 | K5: Revue processus obj. | L5: ='Zoom Indicateurs 2025'!C8 -> 10 | M5: Revue direction Obj. | N5: ='Zoom Indicateurs 2025'!C7 -> 5 | P5: Objectif taux d'évaluation : | R5: ='Zoom Indicateurs 2025'!$C$9 -> 0.95 | S5: Objectif taux de conformité | U5: ='Zoom Indicateurs 2025'!$C$10 -> 0.85 | W5: Tx Evaluation | Y5: ='Zoom Indicateurs 2025'!D11 -> 0.99 | Z5: Tx conformité | AB5: ='Zoom Indicateurs 2025'!D12 -> 0.92
B6: Audit terrain réalisé | C6: ='Zoom Indicateurs 2025'!D5 -> 4 | D6: FAI réalisé | E6: ='Zoom Indicateurs 2025'!D4 -> 0 | F6: fiche sécurité réalisé | G6: ='Zoom Indicateurs 2025'!D3 -> 9 | I6: Audit pr. réalisé | J6: ='Zoom Indicateurs 2025'!D6 -> 8 | K6: Revue pr. réalisé | L6: ='Zoom Indicateurs 2025'!D8 -> 5 | M6: Revue dir. Réalsié | N6: ='Zoom Indicateurs 2025'!D7 -> 5 | P6: TE réalisée France | R6: ='Zoom Indicateurs 2025'!$D$9 -> 0.97 | S6: TC réalisé France | U6: ='Zoom Indicateurs 2025'!$D$10 -> 0.91 | W6: Tx Eval objectif | Y6: ='Zoom Indicateurs 2025'!C11 -> 0.95 | Z6: Tx Conf objectif | AB6: ='Zoom Indicateurs 2025'!C12 -> 0.8
P7: TE réalisée Luxembourg | R7: ='Zoom Indicateurs 2025'!$D$11 -> 0.99 | S7: TC réalisé Luxembourg | U7: ='Zoom Indicateurs 2025'!D12 -> 0.92
AD26: Nombre d'accident sans Arrêt
B27: Indicateur spécifique AB Serve | AD27: obj. annuel = | AF27: ='Zoom Indicateurs 2025'!C24 -> 2 | AG27: cumul = | AI27: ='Zoom Indicateurs 2025'!D24 -> 3
AK28: Nombre d'AT AB Serve
B29: Taux de fréquence AB Serve | P29: Nombre de réclamations et d'incidents client | W29: Veille réglementaire France | AK29: Nombre d'analyse évènements indésirables réalisées ATA AB Serve
B30: Taux de gravité AB Serve | P30: obj.réclamation < | R30: ='Zoom Indicateurs 2025'!C28 -> 10 | S30: cumul réclamation = | U30: ='Zoom Indicateurs 2025'!D28 -> 2 | W30: Tx Evaluation | Y30: ='Zoom Indicateurs 2025'!$D$9 -> 0.97 | Z30: Tx conformité | AB30: ='Zoom Indicateurs 2025'!$D$10 -> 0.91 | AK30: Taux d'analyse AB Serve
B31: TF cumul | C31: ='Zoom Indicateurs 2025'!D22 -> 19.26 | E31: TG cumul | F31: ='Zoom Indicateurs 2025'!Q23 -> 0.32 | I31: Pourcentage d'analyse d'AT avec ou sans Arrêt | W31: Tx Eval objectif | Y31: ='Zoom Indicateurs 2025'!$C$9 -> 0.95 | Z31: Tx Conf objectif | AB31: ='Zoom Indicateurs 2025'!$C$10 -> 0.85
B32: TF objectif | C32: ='Zoom Indicateurs 2025'!C22 -> 15 | E32: TG objectif | F32: ='Zoom Indicateurs 2025'!C23 -> 0.35 | I32: obj. annuel = | N32: ='Zoom Indicateurs 2025'!C27 -> 1
I33: Nbre à faire = | K33: ='Zoom Indicateurs 2025'!C26 -> - | L33: Réalisée = | N33: ='Zoom Indicateurs 2025'!D26 -> 5
AD42: Nombre d'accident avec Arrêt
AD43: obj. annuel = | AF43: ='Zoom Indicateurs 2025'!C25 -> 1 | AG43: cumul = | AI43: ='Zoom Indicateurs 2025'!D25 -> 2
B52: Indicateur Spécifique VALORIS
B54: Taux de fréquence (12 mois glissants) | I54: Nombre d'AT Valoris Emploi | P54: Nombre de réclamations et d'incidents client
B55: Taux de gravité (12 mois glissants) | I55: Taux d'analyse Valoris Emploi | P55: obj.réclamation > | R55: ='Zoom Indicateurs 2025'!C37 -> 1 | S55: cumul réclamation = | U55: ='Zoom Indicateurs 2025'!D37 -> 0
B56: TF cumul | C56: ='Zoom Indicateurs 2025'!D30 -> 53.47 | E56: TG cumul | F56: ='Zoom Indicateurs 2025'!D31 -> 0.67 | I56: ATA = accident avec arret | L56: ATSA = accident sans arret
B57: TF objectif | C57: ='Zoom Indicateurs 2025'!C30 -> 25 | E57: TG objectif | F57: ='Zoom Indicateurs 2025'!C31 -> 0.8 | I57: AT trajet = accident de trajet
B77: AB Serve Industries
AB78: Nombre d'accident AB Serve Industries
B79: Taux de fréquence AB Serve Industries | I79: Nombre d'AT AB Serve Industries | W79: 2025 | X79: 2024 | Y79: 2023 | Z79: 2022 | AB79: Taux de gravité AB Serve Industries
B80: Taux de gravité AB Serve Industries | I80: Nb d'analyse évènements indésirables réalisées ATA AB Serve Industries | V80: TF | W80: 64.24 | X80: 64.24 | Y80: 0 | Z80: 85.35 | AB80: AT A | AD80: ='Zoom Indicateurs 2025'!D49 -> 10 | AE80: AT SA | AG80: ='Zoom Indicateurs 2025'!D48 -> 10
B81: TF cumul | C81: ='Zoom Indicateurs 2025'!D46 -> 64.14 | E81: TG cumul | F81: ='Zoom Indicateurs 2025'!D47 -> 2.28 | I81: Taux d'analyse AB Serve Industries | V81: TG | W81: 2.28 | X81: 3.53 | Y81: 1.5 | Z81: 6.28 | AB81: AT A objectif | AD81: ='Zoom Indicateurs 2025'!C49 -> 3 | AE81: AT SA objectif | AG81: ='Zoom Indicateurs 2025'!C48 -> 3
B82: TF objectif | C82: ='Zoom Indicateurs 2025'!C46 -> 50 | E82: TG objectif | F82: ='Zoom Indicateurs 2025'!C47 -> 1
B103: AB Serve Group ( Chantier Luxembourg )
B105: Taux de fréquence AB Serve Group (Exploitation) | I105: Nombre d'AT AB Serve Group
B106: Taux de gravité AB Serve (Exploitation) | I106: Nombre d'analyse évènements indésirables réalisées ATA AB Serve Group
B107: TF cumul | C107: ='Zoom Indicateurs 2025'!D14 -> 0 | E107: TG cumul | F107: ='Zoom Indicateurs 2025'!D15 -> 0 | I107: Taux d'analyse AB Serve Group
B108: TF objectif | C108: ='Zoom Indicateurs 2025'!C14 -> 18 | E108: TG objectif | F108: ='Zoom Indicateurs 2025'!C15 -> 0.5
B129: AB Serve Germany
B131: Taux de fréquence AB Serve Group (Exploitation) | I131: Nombre d'AT AB Serve Group
B132: Taux de gravité AB Serve (Exploitation) | I132: Nombre d'analyse évènements indésirables réalisées ATA AB Serve Group
B133: TF cumul | C133: ='Zoom Indicateurs 2025'!D39 -> 0 | E133: TG cumul | F133: ='Zoom Indicateurs 2025'!D40 -> 0 | I133: Taux d'analyse AB Serve Group
B134: TF objectif | C134: ='Zoom Indicateurs 2025'!C39 -> 40 | E134: TG objectif | F134: ='Zoom Indicateurs 2025'!C40 -> 0.4

Sheet Objectifs 2026
B2: Indicateurs | C2: Objectifs 2025 | D2: Objectifs 2026
B3: PM02 : Manager, piloter, améliorer le SMQS
B4: Animation sécurité | C4: 11 | D4: 22
B5: Audits terrain réalisées | C5: 8 | D5: 20
B6: Audits processus réalisées | C6: 8 | D6: 8
B7: Revues de direction | C7: 5 | D7: 5
B8: Revues de processus | C8: 10 | D8: 10
B9: Taux d'évaluation règlementaire FRANCE | C9: 0.95 | D9: 0.95
B10: Taux de conformité règlementaire FRANCE | C10: 0.85 | D10: 0.85
B11: Taux d'évaluation règlementaire Luxembourg | C11: 0.95 | D11: 0.95
B12: Taux de conformité règlementaire Luxembourg | C12: 0.8 | D12: 0.8
B13: AB Serve Group (Exploitation)
B14: Taux de fréquence | C14: 18 | D14: 18
B15: Taux de gravité | C15: 0.5 | D15: 0.5
B16: Nombre d'ATSA | C16: 0 | D16: 0
B17: Nombre d'ATA | C17: 0 | D17: 0
B18: Nombre d'analyse | C18: 1 | D18: 1
B19: Taux d'analyse | C19: 1 | D19: 1
B20: Nombre de réclamations et d'incidents client | C20: 8 | D20: 8
B21: AB Serve
B22: Taux de fréquence | C22: 15 | D22: 15
B23: Taux de gravité | C23: 0.35 | D23: 0.3
B24: Nombre d'ATSA | C24: 2 | D24: 2
B25: Nombre d'ATA | C25: 1 | D25: 1
B26: Nombre d'analyse | C26: 1 | D26: 1
B27: Taux d'analyse | C27: 1 | D27: 1
B28: Nombre de réclamations et d'incidents client | C28: 10 | D28: 8
B29: Valoris Emploi
B30: Taux de fréquence | C30: 45 | D30: 45
B31: Taux de gravité | C31: 1.5 | D31: 1.5
B32: Nombre d'ATA | C32: - | D32: -
B33: Nombre d'ATSA | C33: - | D33: -
B34: nombre d'AT trajet | C34: - | D34: -
B35: Nombre d'analyse réalisées ATA | C35: - | D35: -
B36: Taux d'analyse ATA | C36: 0.2 | D36: 0.2
B37: Nombre de réclamations et d'incidents client | C37: 2 | D37: 2
B38: AB Serve GERMANY
B39: Taux de fréquence | C39: 40 | D39: 40
B40: Taux de gravité | C40: 0.4 | D40: 0.4
B41: Nombre d'ATSA | C41: - | D41: -
...

Sheet Détails1
A1: Détails pou for Somme de Total - Processus : Conforme
A3: Processus | B3: PM02 | C3: PR01 | D3: PR04 | E3: PR042 | F3: Total
A4: Conforme | B4: 18 | C4: 18 | D4: 16 | E4: 20 | F4: 72

Sheet Indicateur audit processus
G3: Étiquettes de lignes | H3: Somme de Total | I3: Somme de Total2
G4: Conforme | H4: 110 | I4: 0.78571429
G5: Défauts isolés | H5: 13 | I5: 0.092857143
G6: Non-conforme | H6: 2 | I6: 0.014285714
B7: AB Serve | G7: Non audité | H7: 15 | I7: 0.10714286
G8: Total général | H8: 140 | I8: 1
B11: Processus | C11: PM02 | D11: PR01 | E11: PR02 | F11: PR04 | G11: PR04 | H11: PS01 | I11: Total
B12: Conforme | C12: 18 | D12: 18 | E12: 17 | F12: 16 | G12: 22 | H12: 19 | I12: =SUM(C12:H12) -> 110
B13: Défauts isolés | C13: 2 | D13: 1 | E13: 8 | F13: 2 | G13: 0 | H13: 0 | I13: =SUM(C13:H13) -> 13
B14: Non-conforme | C14: 0 | D14: 0 | E14: 2 | F14: 0 | G14: 0 | H14: 0 | I14: =SUM(C14:H14) -> 2
B15: Non audité | C15: 0 | D15: 3 | E15: 0 | F15: 9 | G15: 2 | H15: 1 | I15: =SUM(C15:H15) -> 15
B22: AB Serve Industries
B24: Processus | C24: PM02 | D24: PR01 | E24: PR02 | F24: PS01 | G24: PS02 | H24: Total
B25: Conforme | C25: 18 | D25: 18 | E25: 17 | F25: 19 | G25: 23 | H25: =SUM(C25:G25) -> 95
B26: Défauts isolés | C26: 2 | D26: 1 | E26: 8 | F26: 0 | G26: 1 | H26: =SUM(C26:G26) -> 12
B27: Non-conforme | C27: 0 | D27: 0 | E27: 2 | F27: 0 | G27: 0 | H27: =SUM(C27:G27) -> 2
B28: Non audité | C28: 0 | D28: 3 | E28: 0 | F28: 1 | G28: 3 | H28: =SUM(C28:G28) -> 7
I31: Étiquettes de lignes | J31: Somme de Total | K31: Somme de Total2
I32: Conforme | J32: 95 | K32: 0.81896552
I33: Défauts isolés | J33: 12 | K33: 0.10344828
I34: Non audité | J34: 7 | K34: 0.060344828
I35: Non-conforme | J35: 2 | K35: 0.017241379
I36: Total général | J36: 116 | K36: 1
B46: Valoris Emploi
B48: Processus | C48: PM02 | D48: PR01 | E48: PR07 | F48: PS01 | G48: PS02 | H48: Total
B49: Conforme | C49: 18 | D49: 18 | E49: 23 | F49: 19 | G49: 23 | H49: =SUM(C49:G49) -> 101 | J49: Étiquettes de lignes | K49: Somme de Total | L49: Somme de Total2
B50: Défauts isolés | C50: 2 | D50: 1 | E50: 2 | F50: 0 | G50: 1 | H50: =SUM(C50:G50) -> 6 | J50: Conforme | K50: 101 | L50: 0.86324786
B51: Non-conforme | C51: 0 | D51: 0 | E51: 2 | F51: 0 | G51: 0 | H51: =SUM(C51:G51) -> 2 | J51: Défauts isolés | K51: 6 | L51: 0.051282051
B52: Non audité | C52: 0 | D52: 3 | E52: 1 | F52: 1 | G52: 3 | H52: =SUM(C52:G52) -> 8 | J52: Non audité | K52: 8 | L52: 0.068376068
J53: Non-conforme | K53: 2 | L53: 0.017094017
J54: Total général | K54: 117 | L54: 1

Sheet Synthèse PR07 2024
B1: Zoom Indicateurs PR07 2024 : Représentation Graphique
B2: Indicateurs AB Serve France
B4: ='Zoom Indicateurs 2025'!#REF! -> #REF! | I4: ='Zoom Indicateurs 2025'!#REF! -> #REF! | P4: ='Zoom Indicateurs 2025'!#REF! -> #REF!
B5: Objectif 2024 = | D5: ='Zoom Indicateurs 2025'!#REF! -> #REF! | E5: Cumul 2024 = | G5: ='Zoom Indicateurs 2025'!#REF! -> #REF! | I5: Objectif 2024 = | K5: ='Zoom Indicateurs 2025'!#REF! -> #REF! | L5: Cumul 2024 = | N5: ='Zoom Indicateurs 2025'!#REF! -> #REF! | P5: Objectif 2024 = | R5: ='Zoom Indicateurs 2025'!#REF! -> #REF! | S5: Cumul 2024 = | U5: ='Zoom Indicateurs 2025'!#REF! -> #REF!
B24: ='Zoom Indicateurs 2025'!#REF! -> #REF!
B25: Objectif 2024 = | D25: ='Zoom Indicateurs 2025'!#REF! -> #REF! | E25: Cumul 2024 = | G25: ='Zoom Indicateurs 2025'!#REF! -> #REF!
